Workbook

Sheet AREA_TIPO_ATTO_MODELLO
A1: Gruppo | B1: AREA | C1: ID_CONF_TIPO_ATTO | D1: ID_MODELLO_ATTO | E1: DESCRIZIONE_TIPO_ATTO | F1: DESCRIZIONE_MODELLO | G1: DICHIARANTE | H1: Note | I1: Conteggio | J1: Frequenza | K1: Usecase ANSC
B2: CITTADINANZE | C2: 501 | D2: 001 | E2: GIURAMENTO A ROMA | F2: GIURAMENTO A ROMA | I2: #N/A
B3: CITTADINANZE | C3: 502 | D3: 002 | E3: TRASCRIZIONE A ROMA | F3: TRASCRIZIONE A ROMA | I3: #N/A
B4: CITTADINANZE | C4: 503 | D4: 003 | E4: Concessione - Estero | F4: CONCESSIONE DA ESTERO | I4: 342 | J4: Media
B5: CITTADINANZE | C5: 504 | D5: 004 | E5: Art. 14 L. 91/92 | F5: ART. 14 | I5: 3995 | J5: Elevatissima
B6: CITTADINANZE | C6: 505 | D6: 005 | E6: ACQUISTO/RIACQUISTO RICON. MINORI | F6: ACQUISTO/RIACQUISTO RICON. MINORI | I6: #N/A
B7: CITTADINANZE | C7: 506 | D7: 006 | E7: Art. 2 comma 2 | F7: DICHIARAZIONE ART.2 COMMA 2 | I7: 2 | J7: Bassa
B8: CITTADINANZE | C8: 507 | D8: 007 | E8: Art. 2 comma 2 - Trascrizione | F8: TRASC. ACCERTAMENTO ART.2 COMMA 2 | I8: 2 | J8: Bassa
B9: CITTADINANZE | C9: 508 | D9: 008 | E9: Accertamento - Art. 16 | F9: ACCERTAMENTO ART.16 | I9: 4 | J9: Bassa
B10: CITTADINANZE | C10: 509 | D10: 009 | E10: Art. 4 comma 2 | F10: DICHIARAZIONE ART.4 COMMA 2 | I10: 2029 | J10: Elevatissima
B11: CITTADINANZE | C11: 510 | D11: 010 | E11: DICHIARAZIONE ART.4 COMMA 1 | F11: DICHIARAZIONE ART.4 COMMA 1 | I11: #N/A
B12: CITTADINANZE | C12: 511 | D12: 011 | E12: TRASC. ACCERTAMENTO ART.4 COMMA 1 | F12: TRASC. ACCERTAMENTO ART.4 COMMA 1 | I12: #N/A
B13: CITTADINANZE | C13: 512 | D13: 012 | E13: Art. 4 comma 2 - Trascrizione | F13: TRASC. ACCERTAMENTO ART.4 COMMA 2 | I13: 2029 | J13: Elevatissima
B14: CITTADINANZE | C14: 513 | D14: 013 | E14: Art. 13 Let. C - Roma | F14: DICHIARAZIONE ART.13 LET. C ROMA | I14: 8 | J14: Bassa
B15: CITTADINANZE | C15: 514 | D15: 014 | E15: Art. 13 Let. C - Roma - Trascrizione | F15: TRASC. ACCERTAMENTO ART.13 LET. C ROMA | I15: 8 | J15: Bassa
B16: CITTADINANZE | C16: 515 | D16: 015 | E16: Art. 13 Let. C - Dich. Acc. Consolato - Estero - Trasc. | F16: TRASC. ATTESTAZIONE ART.13 LET. C CONSOLATO | I16: #N/A
B17: CITTADINANZE | C17: 516 | D17: 025 | E17: Art. 13 Let. C - In attesa Cert. Resid. - Estero | F17: TRASC. ACCERT. ART. 13 LET. C ESTERO | I17: #N/A
B18: CITTADINANZE | C18: 517 | D18: 017 | E18: Art. 13 Let. D - Residenti | F18: TRASC. ACCERT. ART. 13 LET. D | I18: 1 | J18: Bassa
B19: CITTADINANZE | C19: 518 | D19: 018 | E19: Art. 13 Let. C - Dich. Acc. Consolato - Estero | F19: TRASC. ACCERT. ART. 13 LET. C CONSOLATO | I19: #N/A
B20: CITTADINANZE | C20: 519 | D20: 020 | E20: Perdita per Naturalizzazione - Sindaco | F20: PERDITA PER NATURALIZZAZIONE | I20: #N/A
B21: CITTADINANZE | C21: 520 | D21: 022 | E21: Perdita per Iure Loci | F21: PERDITA PER IURE LOCI | I21: #N/A
B22: CITTADINANZE | C22: 521 | D22: 021 | E22: Perdita per Disconoscimento | F22: PERDITA PER DISCONOSCIMENTO | I22: #N/A
B23: CITTADINANZE | C23: 522 | D23: 023 | E23: RINUNCIA CITTADINANZA ART. 11 | F23: RINUNCIA CITTADINANZA ART. 11 | I23: #N/A
B24: CITTADINANZE | C24: 523 | D24: 024 | E24: Art. 13 Let. D - Rinuncia al Riacquisto | F24: RINUNCIA AL RIACQUISTO - DICHIARAZIONE | I24: #N/A
B25: CITTADINANZE | C25: 524 | D25: 016 | E25: Art. 13 Let. C - Acc. Req. Sindaco - Estero | F25: TRASC. ACCERT. ART. 13 LET. C ESTERO | I25: 3 | J25: Bassa
B26: CITTADINANZE | C26: 525 | D26: 026 | E26: Art. 13 Let. D - Rinuncia al Riacquisto - Trasc. | F26: RINUNCIA AL RIACQUISTO - TRASCRIZIONE | I26: #N/A
B27: CITTADINANZE | C27: 526 | D27: 027 | E27: Cittadinanza a testo libero | F27: TESTO LIBERO | I27: 217 | J27: Media
B28: CITTADINANZE | C28: 527 | D28: 032 | E28: Art. 10 comma 2 L. 555/1912 - Console | F28: ATTESTAZIONE ART.10 COMMA 2 L. 555/1912 - CONSOLE | I28: #N/A
B29: CITTADINANZE | C29: 528 | D29: 032 | E29: Art. 10 comma 2 L. 555/1912 - Sindaco | F29: ATTESTAZIONE ART.10 COMMA 2 L. 555/1912 - CONSOLE | I29: #N/A
B30: CITTADINANZE | C30: 529 | D30: 034 | E30: Art. 3 comma 1 - Adozioni | F30: ACQUISTO PER ADOZIONE | I30: 42 | J30: Bassa
B31: CITTADINANZE | C31: 530 | D31: 039 | E31: Cittadinanza senza atto | F31: CITTADINANZA SENZA ATTO | I31: 264 | J31: Media
B32: CITTADINANZE | C32: 531 | D32: 005 | E32: Art. 2 comma 1 - da Sindaco | F32: ACQUISTO/RIACQUISTO RICON. MINORI | I32: 21 | J32: Bassa
B33: CITTADINANZE | C33: 532 | D33: 005 | E33: Art. 2 comma 1 - da Console | F33: ACQUISTO/RIACQUISTO RICON. MINORI | I33: #N/A
B34: CITTADINANZE | C34: 533 | D34: 001 | E34: Art. 5 e Art. 9 - Giuramento | F34: GIURAMENTO A ROMA | I34: 8632 | J34: Elevatissima
B35: CITTADINANZE | C35: 534 | D35: 002 | E35: Art. 5 e Art. 9 - Trascrizione | F35: TRASCRIZIONE A ROMA | I35: 8624 | J35: Elevatissima
B36: CITTADINANZE | C36: 535 | D36: 017 | E36: Art. 13 Let. D - Casi Pregressi | F36: TRASC. ACCERT. ART. 13 LET. D | I36: #N/A
B37: CITTADINANZE | C37: 536 | D37: 020 | E37: Perdita per Naturalizzazione - Console | F37: PERDITA PER NATURALIZZAZIONE | I37: 3 | J37: Bassa
B38: DECESSI | C38: 301 | D38: 01 | E38: MORTE IN ABITAZIONE A ROMA | F38: MORTE IN ABITAZIONE A ROMA | I38: 24266 | J38: Elevatissima | K38: 2101
B39: DECESSI | C39: 302 | D39: 02 | E39: MORTE IN ABITAZIONE FUORI ROMA | F39: MORTE IN ABITAZIONE FUORI ROMA | H39: Si tratta di trascrizioni di atti di stato civile da altro comune; superati dall'introduzione degli atti digitali. | I39: 2083 | J39: Elevatissima
B40: DECESSI | C40: 303 | D40: 03 | E40: MORTE IN STRUTTURA SANITARIA A ROMA | F40: MORTE IN OSPEDALE A ROMA | I40: 21518 | J40: Elevatissima | K40: 2102
...

Sheet Conteggi
A1: ID_TIPO_ATTO | B1: COUNT(*) | C1: Censimento
A2: 301 | B2: 24266 | C2: =VLOOKUP(A2,AREA_TIPO_ATTO_MODELLO!$C:$C,1,FALSE) -> 301
A3: 303 | B3: 21518 | C3: =VLOOKUP(A3,AREA_TIPO_ATTO_MODELLO!$C:$C,1,FALSE) -> 303
A4: 1640 | B4: 11118 | C4: =VLOOKUP(A4,AREA_TIPO_ATTO_MODELLO!$C:$C,1,FALSE) -> 1640
A5: 533 | B5: 8632 | C5: =VLOOKUP(A5,AREA_TIPO_ATTO_MODELLO!$C:$C,1,FALSE) -> 533
A6: 534 | B6: 8624 | C6: =VLOOKUP(A6,AREA_TIPO_ATTO_MODELLO!$C:$C,1,FALSE) -> 534
A7: 1574 | B7: 626 | C7: =VLOOKUP(A7,AREA_TIPO_ATTO_MODELLO!$C:$C,1,FALSE) -> 1574
A8: 1593 | B8: 6148 | C8: =VLOOKUP(A8,AREA_TIPO_ATTO_MODELLO!$C:$C,1,FALSE) -> 1593
A9: 11 | B9: 5928 | C9: =VLOOKUP(A9,AREA_TIPO_ATTO_MODELLO!$C:$C,1,FALSE) -> 11
A10: 1515 | B10: 5628 | C10: =VLOOKUP(A10,AREA_TIPO_ATTO_MODELLO!$C:$C,1,FALSE) -> 1515
A11: 1646 | B11: 5085 | C11: =VLOOKUP(A11,AREA_TIPO_ATTO_MODELLO!$C:$C,1,FALSE) -> 1646
A12: 504 | B12: 3995 | C12: =VLOOKUP(A12,AREA_TIPO_ATTO_MODELLO!$C:$C,1,FALSE) -> 504
A13: 120 | B13: 3939 | C13: =VLOOKUP(A13,AREA_TIPO_ATTO_MODELLO!$C:$C,1,FALSE) -> 120
... A163: 1665 | B163: 1 | C163: =VLOOKUP(A163,AREA_TIPO_ATTO_MODELLO!$C:$C,1,FALSE) -> 1665
